<?xml version="1.0" encoding="utf-8"?>
<!-- This URDF was automatically created by SolidWorks to URDF Exporter! Originally created by Stephen Brawner (brawner@gmail.com) 
     Commit Version: 1.6.0-4-g7f85cfe  Build Version: 1.6.7995.38578
     For more information, please see http://wiki.ros.org/sw_urdf_exporter -->
<robot
  name="ATS">
  <link
    name="base_link">
    <inertial>
      <origin
        xyz="-1.8545E-11 8.5039E-12 0.026958"
        rpy="0 0 0" />
      <mass
        value="1.0462" />
      <inertia
        ixx="0.0043365"
        ixy="1.4227E-07"
        ixz="8.5427E-14"
        iyy="0.0043365"
        iyz="-9.5004E-14"
        izz="0.0080097" />
    </inertial>
    <visual>
      <origin
        xyz="0 0 0"
        rpy="0 0 0" />
      <geometry>
        <mesh
          filename="package://ATS/meshes/base_link.obj" />
      </geometry>
      <material
        name="">
        <color
          rgba="0.79216 0.81961 0.93333 1" />
      </material>
    </visual>
    <collision>
      <origin
        xyz="0 0 0"
        rpy="0 0 0" />
      <geometry>
        <mesh
          filename="package://ATS/meshes/base_link.obj" />
      </geometry>
    </collision>
  </link>
  <link
    name="link1">
    <inertial>
      <origin
        xyz="-0.0049281 0.14856 0.014146"
        rpy="0 0 0" />
      <mass
        value="2.6274" />
      <inertia
        ixx="0.013459"
        ixy="-0.00024243"
        ixz="0.00013078"
        iyy="0.018778"
        iyz="0.002281"
        izz="0.021517" />
    </inertial>
    <visual>
      <origin
        xyz="0 0 0"
        rpy="0 0 0" />
      <geometry>
        <mesh
          filename="package://ATS/meshes/link1.obj" />
      </geometry>
      <material
        name="">
        <color
          rgba="0.79216 0.81961 0.93333 1" />
      </material>
    </visual>
    <collision>
      <origin
        xyz="0 0 0"
        rpy="0 0 0" />
      <geometry>
        <mesh
          filename="package://ATS/meshes/link1.obj" />
      </geometry>
    </collision>
  </link>
  <joint
    name="joint1"
    type="continuous">
    <origin
      xyz="0 0 0"
      rpy="1.5708 0 0" />
    <parent
      link="base_link" />
    <child
      link="link1" />
    <axis
      xyz="0 1 0" />
    <limit
      effort="0"
      velocity="0" />
    <dynamics
      damping="0.1"
      friction="0" />
  </joint>
  <link
    name="link2">
    <inertial>
      <origin
        xyz="-0.0094763 0.026223 -0.040506"
        rpy="0 0 0" />
      <mass
        value="1.3987" />
      <inertia
        ixx="0.0046118"
        ixy="2.8175E-06"
        ixz="8.7703E-06"
        iyy="0.0039548"
        iyz="0.00013372"
        izz="0.0011478" />
    </inertial>
    <visual>
      <origin
        xyz="0 0 0"
        rpy="0 0 0" />
      <geometry>
        <mesh
          filename="package://ATS/meshes/link2.obj" />
      </geometry>
      <material
        name="">
        <color
          rgba="0.75294 0.75294 0.75294 1" />
      </material>
    </visual>
    <collision>
      <origin
        xyz="0 0 0"
        rpy="0 0 0" />
      <geometry>
        <mesh
          filename="package://ATS/meshes/link2.obj" />
      </geometry>
    </collision>
  </link>
  <joint
    name="joint2"
    type="revolute">
    <origin
      xyz="0 0.27175 -0.017154"
      rpy="0 0 0" />
    <parent
      link="link1" />
    <child
      link="link2" />
    <axis
      xyz="1 0 0" />
    <limit
      lower="-1.57"
      upper="0"
      effort="0"
      velocity="0" />
    <dynamics
      damping="0.1"
      friction="0" />
  </joint>
</robot>
